DataError
sqlalchemy.exc.DataError: (psycopg2.errors.StringDataRightTruncation) value too long for type character varying(128)

[SQL: INSERT INTO "user" (username, email, password_hash, score) VALUES (%(username)s, %(email)s, %(password_hash)s, %(score)s) RETURNING "user".id]
[parameters: {'username': 'test2', 'email': 'test2@test.com', 'password_hash': 'scrypt:32768:8:1$tMY9kdv8PeKAJepH$bf71c24503a93f9846c1d4dcbe06607658162ee60dc70827f85c9bbb64af3bebb1081224ed39e7300f00d6f5b5b847322b3c13c3121ebb5b6734d859e1306882', 'score': 0}]
(Background on this error at: https://sqlalche.me/e/20/9h9h)

Traceback (most recent call last)
File "/home/runner/InfoMapArch/.pythonlibs/lib/python3.11/site-packages/sqlalchemy/engine/base.py", line 1967, in _exec_single_context
self.dialect.do_execute(
^
File "/home/runner/InfoMapArch/.pythonlibs/lib/python3.11/site-packages/sqlalchemy/engine/default.py", line 941, in do_execute
cursor.execute(statement, parameters)
^^^^^^^^^^^^^^^^^^^^^^^^^^^^^^^^^^^^^
The above exception was the direct cause of the following exception:
File "/home/runner/InfoMapArch/.pythonlibs/lib/python3.11/site-packages/flask/app.py", line 1498, in __call__
return self.wsgi_app(environ, start_response)
       ^^^^^^^^^^^^^^^^^^^^^^^^^^^^^^^^^^^^^^
File "/home/runner/InfoMapArch/.pythonlibs/lib/python3.11/site-packages/flask/app.py", line 1476, in wsgi_app
response = self.handle_exception(e)
           ^^^^^^^^^^^^^^^^^^^^^^^^
File "/home/runner/InfoMapArch/.pythonlibs/lib/python3.11/site-packages/flask/app.py", line 1473, in wsgi_app
response = self.full_dispatch_request()
           ^^^^^^^^^^^^^^^^^^^^^^^^^^^^
File "/home/runner/InfoMapArch/.pythonlibs/lib/python3.11/site-packages/flask/app.py", line 882, in full_dispatch_request
rv = self.handle_user_exception(e)
     ^^^^^^^^^^^^^^^^^^^^^^^^^^^^^
File "/home/runner/InfoMapArch/.pythonlibs/lib/python3.11/site-packages/flask/app.py", line 880, in full_dispatch_request
rv = self.dispatch_request()
     ^^^^^^^^^^^^^^^^^^^^^^^
File "/home/runner/InfoMapArch/.pythonlibs/lib/python3.11/site-packages/flask/app.py", line 865, in dispatch_request
return self.ensure_sync(self.view_functions[rule.endpoint])(**view_args)  # type: ignore[no-any-return]
       ^^^^^^^^^^^^^^^^^^^^^^^^^^^^^^^^^^^^^^^^^^^^^^^^^^^^^^^^^^^^^^^^^
File "/home/runner/InfoMapArch/routes/auth.py", line 24, in register
db.session.commit()
^^^^^^^^^^^^^^^^^^^
File "/home/runner/InfoMapArch/.pythonlibs/lib/python3.11/site-packages/sqlalchemy/orm/scoping.py", line 597, in commit
return self._proxied.commit()
       ^^^^^^^^^^^^^^^^^^^^^^
File "/home/runner/InfoMapArch/.pythonlibs/lib/python3.11/site-packages/sqlalchemy/orm/session.py", line 2028, in commit
trans.commit(_to_root=True)
^^^^^^^^^^^^^^^^^^^^^^^^^^^
File "<string>", line 2, in commit
File "/home/runner/InfoMapArch/.pythonlibs/lib/python3.11/site-packages/sqlalchemy/orm/state_changes.py", line 139, in _go
ret_value = fn(self, *arg, **kw)
            ^^^^^^^^^^^^^^^^^^^^
File "/home/runner/InfoMapArch/.pythonlibs/lib/python3.11/site-packages/sqlalchemy/orm/session.py", line 1313, in commit
self._prepare_impl()
^^^^^^^^^^^^^^^^^^^^
File "<string>", line 2, in _prepare_impl
File "/home/runner/InfoMapArch/.pythonlibs/lib/python3.11/site-packages/sqlalchemy/orm/state_changes.py", line 139, in _go
ret_value = fn(self, *arg, **kw)
            ^^^^^^^^^^^^^^^^^^^^
File "/home/runner/InfoMapArch/.pythonlibs/lib/python3.11/site-packages/sqlalchemy/orm/session.py", line 1288, in _prepare_impl
self.session.flush()
^^^^^^^^^^^^^^^^^^^^
File "/home/runner/InfoMapArch/.pythonlibs/lib/python3.11/site-packages/sqlalchemy/orm/session.py", line 4352, in flush
self._flush(objects)
^^^^^^^^^^^^^^^^^^^^
File "/home/runner/InfoMapArch/.pythonlibs/lib/python3.11/site-packages/sqlalchemy/orm/session.py", line 4487, in _flush
with util.safe_reraise():
^^^^^^^^^^^^^^^^^^^^^^^^^^^^^^^^^^^^^^^^^^^^^^^^^
File "/home/runner/InfoMapArch/.pythonlibs/lib/python3.11/site-packages/sqlalchemy/util/langhelpers.py", line 146, in __exit__
raise exc_value.with_traceback(exc_tb)
^^^^^^^^^^^^^^^^^^^^^^^^^^^^^^^^^^^^^^
File "/home/runner/InfoMapArch/.pythonlibs/lib/python3.11/site-packages/sqlalchemy/orm/session.py", line 4448, in _flush
flush_context.execute()
^^^^^^^^^^^^^^^^^^^^^^^
File "/home/runner/InfoMapArch/.pythonlibs/lib/python3.11/site-packages/sqlalchemy/orm/unitofwork.py", line 466, in execute
rec.execute(self)
^^^^^^^^^^^^^^^^^
File "/home/runner/InfoMapArch/.pythonlibs/lib/python3.11/site-packages/sqlalchemy/orm/unitofwork.py", line 642, in execute
util.preloaded.orm_persistence.save_obj(
^
File "/home/runner/InfoMapArch/.pythonlibs/lib/python3.11/site-packages/sqlalchemy/orm/persistence.py", line 93, in save_obj
_emit_insert_statements(
^
File "/home/runner/InfoMapArch/.pythonlibs/lib/python3.11/site-packages/sqlalchemy/orm/persistence.py", line 1233, in _emit_insert_statements
result = connection.execute(
         
File "/home/runner/InfoMapArch/.pythonlibs/lib/python3.11/site-packages/sqlalchemy/engine/base.py", line 1418, in execute
return meth(
       
File "/home/runner/InfoMapArch/.pythonlibs/lib/python3.11/site-packages/sqlalchemy/sql/elements.py", line 515, in _execute_on_connection
return connection._execute_clauseelement(
       
File "/home/runner/InfoMapArch/.pythonlibs/lib/python3.11/site-packages/sqlalchemy/engine/base.py", line 1640, in _execute_clauseelement
ret = self._execute_context(
      
File "/home/runner/InfoMapArch/.pythonlibs/lib/python3.11/site-packages/sqlalchemy/engine/base.py", line 1846, in _execute_context
return self._exec_single_context(
       
File "/home/runner/InfoMapArch/.pythonlibs/lib/python3.11/site-packages/sqlalchemy/engine/base.py", line 1986, in _exec_single_context
self._handle_dbapi_exception(
^
File "/home/runner/InfoMapArch/.pythonlibs/lib/python3.11/site-packages/sqlalchemy/engine/base.py", line 2355, in _handle_dbapi_exception
raise sqlalchemy_exception.with_traceback(exc_info[2]) from e
^^^^^^^^^^^^^^^^^^^^^^^^^^^^^^^^^^^^^^^^^^^^^^^^^^^^^^^^^^^^^
File "/home/runner/InfoMapArch/.pythonlibs/lib/python3.11/site-packages/sqlalchemy/engine/base.py", line 1967, in _exec_single_context
self.dialect.do_execute(
^
File "/home/runner/InfoMapArch/.pythonlibs/lib/python3.11/site-packages/sqlalchemy/engine/default.py", line 941, in do_execute
cursor.execute(statement, parameters)
^^^^^^^^^^^^^^^^^^^^^^^^^^^^^^^^^^^^^
sqlalchemy.exc.DataError: (psycopg2.errors.StringDataRightTruncation) value too long for type character varying(128)

[SQL: INSERT INTO "user" (username, email, password_hash, score) VALUES (%(username)s, %(email)s, %(password_hash)s, %(score)s) RETURNING "user".id]
[parameters: {'username': 'test2', 'email': 'test2@test.com', 'password_hash': 'scrypt:32768:8:1$tMY9kdv8PeKAJepH$bf71c24503a93f9846c1d4dcbe06607658162ee60dc70827f85c9bbb64af3bebb1081224ed39e7300f00d6f5b5b847322b3c13c3121ebb5b6734d859e1306882', 'score': 0}]
(Background on this error at: https://sqlalche.me/e/20/9h9h)
The debugger caught an exception in your WSGI application. You can now look at the traceback which led to the error.
To switch between the interactive traceback and the plaintext one, you can click on the "Traceback" headline. From the text traceback you can also create a paste of it.